<?xml version="1.0" ?>
<!-- =================================================================================== -->
<!-- |    This document was autogenerated by xacro from urdf/arcsys2.xacro             | -->
<!-- |    EDITING THIS FILE BY HAND IS NOT RECOMMENDED                                 | -->
<!-- =================================================================================== -->
<robot name="arcsys2" xmlns:xacro="http://ros.org/wiki/xacro">
  <material name="white">
    <color rgba="1.0 1.0 1.0 1.0"/>
  </material>
  <material name="red">
    <color rgba="1.0 0.0 0.0 1.0"/>
  </material>
  <material name="green">
    <color rgba="0.0 1.0 0.0 1.0"/>
  </material>
  <material name="blue">
    <color rgba="0.0 0.0 1.0 1.0"/>
  </material>
  <!-- Property -->
  <!-- LINK and JOINT -->
  <link name="rail">
    <origin xyz="0 0 0"/>
    <visual>
      <geometry>
        <box size="0.1 10.0 0.1"/>
      </geometry>
      <material name="white"/>
    </visual>
    <collision>
      <geometry>
        <box size="0.1 10.0 0.1"/>
      </geometry>
    </collision>
  </link>
  <joint name="rail_to_shaft_joint" type="prismatic">
    <origin xyz="0 0 1.0"/>
    <parent link="rail"/>
    <child link="shaft"/>
    <axis xyz="0 1 0"/>
    <limit effort="1" lower="-5.0" upper="5.0" velocity="1"/>
  </joint>
  <transmission name="rail_to_shaft_transmission">
    <type>transmission_interface/SimpleTransmission</type>
    <actuator name="rail_to_shaft_actuator">
      <mechanicalReduction>1.0</mechanicalReduction>
      <hardwareInterface>hardware_interface/PositionJointInterface</hardwareInterface>
    </actuator>
    <joint name="rail_to_shaft_joint">
      <hardwareInterface>hardware_interface/PositionJointInterface</hardwareInterface>
    </joint>
  </transmission>
  <link name="shaft">
    <origin xyz="0 0 0"/>
    <visual>
      <geometry>
        <box size="0.1 0.1 2.0"/>
      </geometry>
      <material name="red"/>
    </visual>
    <collision>
      <geometry>
        <box size="0.1 0.1 2.0"/>
      </geometry>
    </collision>
  </link>
  <joint name="shaft_to_arm0_joint" type="prismatic">
    <origin xyz="0.05 0 0.5"/>
    <parent link="shaft"/>
    <child link="arm0"/>
    <axis xyz="0 0 1"/>
    <limit effort="1" lower="-0.5" upper="0.5" velocity="1"/>
  </joint>
  <transmission name="shaft_to_arm0_transmission">
    <type>transmission_interface/SimpleTransmission</type>
    <actuator name="shaft_to_arm0_actuator">
      <mechanicalReduction>1.0</mechanicalReduction>
      <hardwareInterface>hardware_interface/PositionJointInterface</hardwareInterface>
    </actuator>
    <joint name="shaft_to_arm0_joint">
      <hardwareInterface>hardware_interface/PositionJointInterface</hardwareInterface>
    </joint>
  </transmission>
  <link name="arm0">
    <visual>
      <origin xyz="0.05 0 0"/>
      <geometry>
        <box size="0.1 0.1 0.1"/>
      </geometry>
      <material name="green"/>
    </visual>
    <collision>
      <geometry>
        <box size="0.1 0.1 0.1"/>
      </geometry>
    </collision>
  </link>
  <joint name="arm0_to_arm1_joint" type="revolute">
    <origin xyz="0.1 0 0"/>
    <parent link="arm0"/>
    <child link="arm1"/>
    <axis xyz="0 0 1"/>
    <limit effort="1" lower="-1.57079632679" upper="1.57079632679" velocity="1"/>
  </joint>
  <transmission name="arm0_to_arm1_transmission">
    <type>transmission_interface/SimpleTransmission</type>
    <actuator name="arm0_to_arm1_actuator">
      <mechanicalReduction>1.0</mechanicalReduction>
      <hardwareInterface>hardware_interface/PositionJointInterface</hardwareInterface>
    </actuator>
    <joint name="arm0_to_arm1_joint">
      <hardwareInterface>hardware_interface/PositionJointInterface</hardwareInterface>
    </joint>
  </transmission>
  <link name="arm1">
    <visual>
      <origin xyz="0.25 0 0"/>
      <geometry>
        <box size="0.5 0.1 0.1"/>
      </geometry>
      <material name="blue"/>
    </visual>
    <collision>
      <geometry>
        <box size="0.5 0.1 0.1"/>
      </geometry>
    </collision>
  </link>
  <joint name="arm1_to_arm2_joint" type="revolute">
    <origin xyz="0.5 0 0"/>
    <parent link="arm1"/>
    <child link="arm2"/>
    <axis xyz="0 0 1"/>
    <limit effort="1" lower="-1.57079632679" upper="1.57079632679" velocity="1"/>
  </joint>
  <transmission name="arm1_to_arm2_transmission">
    <type>transmission_interface/SimpleTransmission</type>
    <actuator name="arm1_to_arm2_actuator">
      <mechanicalReduction>1.0</mechanicalReduction>
      <hardwareInterface>hardware_interface/PositionJointInterface</hardwareInterface>
    </actuator>
    <joint name="arm1_to_arm2_joint">
      <hardwareInterface>hardware_interface/PositionJointInterface</hardwareInterface>
    </joint>
  </transmission>
  <link name="arm2">
    <visual>
      <origin xyz="0.25 0 0"/>
      <geometry>
        <box size="0.5 0.1 0.1"/>
      </geometry>
      <material name="red"/>
    </visual>
    <collision>
      <geometry>
        <box size="0.5 0.1 0.1"/>
      </geometry>
    </collision>
  </link>
  <joint name="arm2_to_effector_base_joint" type="revolute">
    <origin xyz="0.5 0 0"/>
    <parent link="arm2"/>
    <child link="effector_base"/>
    <axis xyz="0 0 1"/>
    <limit effort="1" lower="-1.57079632679" upper="1.57079632679" velocity="1"/>
  </joint>
  <transmission name="arm2_to_effector_base_transmission">
    <type>transmission_interface/SimpleTransmission</type>
    <actuator name="arm2_to_effector_base_actuator">
      <mechanicalReduction>1.0</mechanicalReduction>
      <hardwareInterface>hardware_interface/PositionJointInterface</hardwareInterface>
    </actuator>
    <joint name="arm2_to_effector_base_joint">
      <hardwareInterface>hardware_interface/PositionJointInterface</hardwareInterface>
    </joint>
  </transmission>
  <link name="effector_base">
    <visual>
      <origin xyz="0.125 0 0"/>
      <geometry>
        <box size="0.25 0.1 0.1"/>
      </geometry>
      <material name="green"/>
    </visual>
    <collision>
      <geometry>
        <box size="0.25 0.1 0.1"/>
      </geometry>
    </collision>
  </link>
  <joint name="effector_base_to_effector_end_joint" type="revolute">
    <origin xyz="0.25 0 0"/>
    <parent link="effector_base"/>
    <child link="effector_end"/>
    <axis xyz="1 0 0"/>
    <limit effort="1" lower="-1.57079632679" upper="1.57079632679" velocity="1"/>
  </joint>
  <transmission name="effector_base_to_effector_end_transmission">
    <type>transmission_interface/SimpleTransmission</type>
    <actuator name="effector_base_to_effector_end_actuator">
      <mechanicalReduction>1.0</mechanicalReduction>
      <hardwareInterface>hardware_interface/PositionJointInterface</hardwareInterface>
    </actuator>
    <joint name="effector_base_to_effector_end_joint">
      <hardwareInterface>hardware_interface/PositionJointInterface</hardwareInterface>
    </joint>
  </transmission>
  <link name="effector_end">
    <visual>
      <origin xyz="0.125 0 0"/>
      <geometry>
        <box size="0.25 0.1 0.1"/>
      </geometry>
      <material name="blue"/>
    </visual>
    <collision>
      <geometry>
        <box size="0.25 0.1 0.1"/>
      </geometry>
    </collision>
  </link>
  <!-- Macro Definition -->
</robot>

